Workbook

Sheet Summary
A1: Satellite corroboration — stage 6 verdicts
A2: All counts are formulas over the Verdicts sheet (100 events, rules fixed 28 Oct 2026). 'Observable' = events with a site point, excluding 'not observable'. 95% intervals: Wilson.
A4: Site level
A5: Split | B5: Events corroborated | C5: Observable events | D5: Rate | E5: 95% low | F5: 95% high | G5: Controls 'corroborated' | H5: Controls | I5: False-alarm rate | J5: 95% low | K5: 95% high
A6: Test half | B6: =COUNTIFS(Verdicts!$D$2:$D$101,"<>negative_control",Verdicts!$C$2:$C$101,"test",Verdicts!$I$2:$I$101,"corroborated") -> 8 | C6: =COUNTIFS(Verdicts!$D$2:$D$101,"<>negative_control",Verdicts!$C$2:$C$101,"test",Verdicts!$I$2:$I$101,"<>not_assessable_no_site",Verdicts!$I$2:$I$101,"<>not_observable") -> 16 | D6: =IF(C6=0,"",B6/C6) -> 0.5 | E6: =IF(C6=0,"",MAX(0,((B6/C6)+1.96^2/(2*C6)-1.96*SQRT((B6/C6)*(1-(B6/C6))/C6+1.96^2/(4*C6^2)))/(1+1.96^2/C6))) -> 0.27999238 | F6: =IF(C6=0,"",MIN(1,((B6/C6)+1.96^2/(2*C6)+1.96*SQRT((B6/C6)*(1-(B6/C6))/C6+1.96^2/(4*C6^2)))/(1+1.96^2/C6))) -> 0.72000762 | G6: =COUNTIFS(Verdicts!$D$2:$D$101,"negative_control",Verdicts!$C$2:$C$101,"test",Verdicts!$I$2:$I$101,"corroborated") -> 0 | H6: =COUNTIFS(Verdicts!$D$2:$D$101,"negative_control",Verdicts!$C$2:$C$101,"test") -> 10 | I6: =IF(H6=0,"",G6/H6) -> 0 | J6: =IF(H6=0,"",MAX(0,((G6/H6)+1.96^2/(2*H6)-1.96*SQRT((G6/H6)*(1-(G6/H6))/H6+1.96^2/(4*H6^2)))/(1+1.96^2/H6))) -> 0 | K6: =IF(H6=0,"",MIN(1,((G6/H6)+1.96^2/(2*H6)+1.96*SQRT((G6/H6)*(1-(G6/H6))/H6+1.96^2/(4*H6^2)))/(1+1.96^2/H6))) -> 0.27754017
A7: Calibration half | B7: =COUNTIFS(Verdicts!$D$2:$D$101,"<>negative_control",Verdicts!$C$2:$C$101,"calibration",Verdicts!$I$2:$I$101,"corroborated") -> 9 | C7: =COUNTIFS(Verdicts!$D$2:$D$101,"<>negative_control",Verdicts!$C$2:$C$101,"calibration",Verdicts!$I$2:$I$101,"<>not_assessable_no_site",Verdicts!$I$2:$I$101,"<>not_observable") -> 21 | D7: =IF(C7=0,"",B7/C7) -> 0.42857143 | E7: =IF(C7=0,"",MAX(0,((B7/C7)+1.96^2/(2*C7)-1.96*SQRT((B7/C7)*(1-(B7/C7))/C7+1.96^2/(4*C7^2)))/(1+1.96^2/C7))) -> 0.24469699 | F7: =IF(C7=0,"",MIN(1,((B7/C7)+1.96^2/(2*C7)+1.96*SQRT((B7/C7)*(1-(B7/C7))/C7+1.96^2/(4*C7^2)))/(1+1.96^2/C7))) -> 0.63453784 | G7: =COUNTIFS(Verdicts!$D$2:$D$101,"negative_control",Verdicts!$C$2:$C$101,"calibration",Verdicts!$I$2:$I$101,"corroborated") -> 0 | H7: =COUNTIFS(Verdicts!$D$2:$D$101,"negative_control",Verdicts!$C$2:$C$101,"calibration") -> 16 | I7: =IF(H7=0,"",G7/H7) -> 0 | J7: =IF(H7=0,"",MAX(0,((G7/H7)+1.96^2/(2*H7)-1.96*SQRT((G7/H7)*(1-(G7/H7))/H7+1.96^2/(4*H7^2)))/(1+1.96^2/H7))) -> 0 | K7: =IF(H7=0,"",MIN(1,((G7/H7)+1.96^2/(2*H7)+1.96*SQRT((G7/H7)*(1-(G7/H7))/H7+1.96^2/(4*H7^2)))/(1+1.96^2/H7))) -> 0.19361342
A8: All | B8: =COUNTIFS(Verdicts!$D$2:$D$101,"<>negative_control",Verdicts!$C$2:$C$101,"*",Verdicts!$I$2:$I$101,"corroborated") -> 17 | C8: =COUNTIFS(Verdicts!$D$2:$D$101,"<>negative_control",Verdicts!$C$2:$C$101,"*",Verdicts!$I$2:$I$101,"<>not_assessable_no_site",Verdicts!$I$2:$I$101,"<>not_observable") -> 37 | D8: =IF(C8=0,"",B8/C8) -> 0.45945946 | E8: =IF(C8=0,"",MAX(0,((B8/C8)+1.96^2/(2*C8)-1.96*SQRT((B8/C8)*(1-(B8/C8))/C8+1.96^2/(4*C8^2)))/(1+1.96^2/C8))) -> 0.31038328 | F8: =IF(C8=0,"",MIN(1,((B8/C8)+1.96^2/(2*C8)+1.96*SQRT((B8/C8)*(1-(B8/C8))/C8+1.96^2/(4*C8^2)))/(1+1.96^2/C8))) -> 0.6161622 | G8: =COUNTIFS(Verdicts!$D$2:$D$101,"negative_control",Verdicts!$C$2:$C$101,"*",Verdicts!$I$2:$I$101,"corroborated") -> 0 | H8: =COUNTIFS(Verdicts!$D$2:$D$101,"negative_control",Verdicts!$C$2:$C$101,"*") -> 26 | I8: =IF(H8=0,"",G8/H8) -> 0 | J8: =IF(H8=0,"",MAX(0,((G8/H8)+1.96^2/(2*H8)-1.96*SQRT((G8/H8)*(1-(G8/H8))/H8+1.96^2/(4*H8^2)))/(1+1.96^2/H8))) -> 0 | K8: =IF(H8=0,"",MIN(1,((G8/H8)+1.96^2/(2*H8)+1.96*SQRT((G8/H8)*(1-(G8/H8))/H8+1.96^2/(4*H8^2)))/(1+1.96^2/H8))) -> 0.12873304
A9: All, without the 2 image-only cases | B9: =B8-COUNTIFS(Verdicts!$D$2:$D$101,"<>negative_control",Verdicts!$I$2:$I$101,"corroborated",Verdicts!$J$2:$J$101,"image") -> 15 | C9: =C8 -> 37 | D9: =IF(C9=0,"",B9/C9) -> 0.40540541 | E9: =IF(C9=0,"",MAX(0,((B9/C9)+1.96^2/(2*C9)-1.96*SQRT((B9/C9)*(1-(B9/C9))/C9+1.96^2/(4*C9^2)))/(1+1.96^2/C9))) -> 0.26346296 | F9: =IF(C9=0,"",MIN(1,((B9/C9)+1.96^2/(2*C9)+1.96*SQRT((B9/C9)*(1-(B9/C9))/C9+1.96^2/(4*C9^2)))/(1+1.96^2/C9))) -> 0.56514317 | G9: Engels E021 and Norfolk Southern E038 rest on one image label each
A11: Site-level verdict counts
A12: Group | B12: corroborated | C12: ambiguous_attribution | D12: weak | E12: not_observable | F12: not_corroborated | G12: not_assessable_no_site | H12: Total
A13: Events | B13: =COUNTIFS(Verdicts!$D$2:$D$101,"<>negative_control",Verdicts!$I$2:$I$101,"corroborated") -> 17 | C13: =COUNTIFS(Verdicts!$D$2:$D$101,"<>negative_control",Verdicts!$I$2:$I$101,"ambiguous_attribution") -> 0 | D13: =COUNTIFS(Verdicts!$D$2:$D$101,"<>negative_control",Verdicts!$I$2:$I$101,"weak") -> 2 | E13: =COUNTIFS(Verdicts!$D$2:$D$101,"<>negative_control",Verdicts!$I$2:$I$101,"not_observable") -> 11 | F13: =COUNTIFS(Verdicts!$D$2:$D$101,"<>negative_control",Verdicts!$I$2:$I$101,"not_corroborated") -> 18 | G13: =COUNTIFS(Verdicts!$D$2:$D$101,"<>negative_control",Verdicts!$I$2:$I$101,"not_assessable_no_site") -> 26 | H13: =SUM(B13:G13) -> 74
A14: Controls | B14: =COUNTIFS(Verdicts!$D$2:$D$101,"negative_control",Verdicts!$I$2:$I$101,"corroborated") -> 0 | C14: =COUNTIFS(Verdicts!$D$2:$D$101,"negative_control",Verdicts!$I$2:$I$101,"ambiguous_attribution") -> 0 | D14: =COUNTIFS(Verdicts!$D$2:$D$101,"negative_control",Verdicts!$I$2:$I$101,"weak") -> 1 | E14: =COUNTIFS(Verdicts!$D$2:$D$101,"negative_control",Verdicts!$I$2:$I$101,"not_observable") -> 11 | F14: =COUNTIFS(Verdicts!$D$2:$D$101,"negative_control",Verdicts!$I$2:$I$101,"not_corroborated") -> 14 | G14: =COUNTIFS(Verdicts!$D$2:$D$101,"negative_control",Verdicts!$I$2:$I$101,"not_assessable_no_site") -> 0 | H14: =SUM(B14:G14) -> 26
A16: Site level by category (all splits)
A17: Category | B17: Corroborated | C17: Observable | D17: Rate | E17: Not observable | F17: No site point
A18: industrial_fire | B18: =COUNTIFS(Verdicts!$D$2:$D$101,"industrial_fire",Verdicts!$I$2:$I$101,"corroborated") -> 5 | C18: =COUNTIFS(Verdicts!$D$2:$D$101,"industrial_fire",Verdicts!$I$2:$I$101,"<>not_assessable_no_site",Verdicts!$I$2:$I$101,"<>not_observable") -> 6 | D18: =IF(C18=0,"",B18/C18) -> 0.83333333 | E18: =COUNTIFS(Verdicts!$D$2:$D$101,"industrial_fire",Verdicts!$I$2:$I$101,"not_observable") -> 2 | F18: =COUNTIFS(Verdicts!$D$2:$D$101,"industrial_fire",Verdicts!$I$2:$I$101,"not_assessable_no_site") -> 9
A19: port_ship_fire | B19: =COUNTIFS(Verdicts!$D$2:$D$101,"port_ship_fire",Verdicts!$I$2:$I$101,"corroborated") -> 5 | C19: =COUNTIFS(Verdicts!$D$2:$D$101,"port_ship_fire",Verdicts!$I$2:$I$101,"<>not_assessable_no_site",Verdicts!$I$2:$I$101,"<>not_observable") -> 10 | D19: =IF(C19=0,"",B19/C19) -> 0.5 | E19: =COUNTIFS(Verdicts!$D$2:$D$101,"port_ship_fire",Verdicts!$I$2:$I$101,"not_observable") -> 1 | F19: =COUNTIFS(Verdicts!$D$2:$D$101,"port_ship_fire",Verdicts!$I$2:$I$101,"not_assessable_no_site") -> 4
A20: large_outdoor_fire | B20: =COUNTIFS(Verdicts!$D$2:$D$101,"large_outdoor_fire",Verdicts!$I$2:$I$101,"corroborated") -> 7 | C20: =COUNTIFS(Verdicts!$D$2:$D$101,"large_outdoor_fire",Verdicts!$I$2:$I$101,"<>not_assessable_no_site",Verdicts!$I$2:$I$101,"<>not_observable") -> 16 | D20: =IF(C20=0,"",B20/C20) -> 0.4375 | E20: =COUNTIFS(Verdicts!$D$2:$D$101,"large_outdoor_fire",Verdicts!$I$2:$I$101,"not_observable") -> 4 | F20: =COUNTIFS(Verdicts!$D$2:$D$101,"large_outdoor_fire",Verdicts!$I$2:$I$101,"not_assessable_no_site") -> 3
A21: small_or_indoor | B21: =COUNTIFS(Verdicts!$D$2:$D$101,"small_or_indoor",Verdicts!$I$2:$I$101,"corroborated") -> 0 | C21: =COUNTIFS(Verdicts!$D$2:$D$101,"small_or_indoor",Verdicts!$I$2:$I$101,"<>not_assessable_no_site",Verdicts!$I$2:$I$101,"<>not_observable") -> 5 | D21: =IF(C21=0,"",B21/C21) -> 0 | E21: =COUNTIFS(Verdicts!$D$2:$D$101,"small_or_indoor",Verdicts!$I$2:$I$101,"not_observable") -> 4 | F21: =COUNTIFS(Verdicts!$D$2:$D$101,"small_or_indoor",Verdicts!$I$2:$I$101,"not_assessable_no_site") -> 10
A23: City level (city point only, no outline, no flare filter)
A24: Group | B24: City-level corroborated | C24: Total | D24: Rate | E24: 95% low | F24: 95% high
A25: All events | B25: =COUNTIFS(Verdicts!$D$2:$D$101,"<>negative_control",Verdicts!$R$2:$R$101,"corroborated") -> 13 | C25: =COUNTIFS(Verdicts!$D$2:$D$101,"<>negative_control") -> 74 | D25: =IF(C25=0,"",B25/C25) -> 0.17567568 | E25: =IF(C25=0,"",MAX(0,((B25/C25)+1.96^2/(2*C25)-1.96*SQRT((B25/C25)*(1-(B25/C25))/C25+1.96^2/(4*C25^2)))/(1+1.96^2/C25))) -> 0.10564109 | F25: =IF(C25=0,"",MIN(1,((B25/C25)+1.96^2/(2*C25)+1.96*SQRT((B25/C25)*(1-(B25/C25))/C25+1.96^2/(4*C25^2)))/(1+1.96^2/C25))) -> 0.27772205
A26: Controls | B26: =COUNTIFS(Verdicts!$D$2:$D$101,"negative_control",Verdicts!$R$2:$R$101,"corroborated") -> 0 | C26: =COUNTIFS(Verdicts!$D$2:$D$101,"negative_control") -> 26 | D26: =IF(C26=0,"",B26/C26) -> 0 | E26: =IF(C26=0,"",MAX(0,((B26/C26)+1.96^2/(2*C26)-1.96*SQRT((B26/C26)*(1-(B26/C26))/C26+1.96^2/(4*C26^2)))/(1+1.96^2/C26))) -> 0 | F26: =IF(C26=0,"",MIN(1,((B26/C26)+1.96^2/(2*C26)+1.96*SQRT((B26/C26)*(1-(B26/C26))/C26+1.96^2/(4*C26^2)))/(1+1.96^2/C26))) -> 0.12873304
A27: Events without a site point | B27: =COUNTIFS(Verdicts!$D$2:$D$101,"<>negative_control",Verdicts!$R$2:$R$101,"corroborated",Verdicts!$I$2:$I$101,"not_assessable_no_site") -> 5 | C27: =COUNTIFS(Verdicts!$D$2:$D$101,"<>negative_control",Verdicts!$I$2:$I$101,"not_assessable_no_site") -> 26 | D27: =IF(C27=0,"",B27/C27) -> 0.19230769 | E27: =IF(C27=0,"",MAX(0,((B27/C27)+1.96^2/(2*C27)-1.96*SQRT((B27/C27)*(1-(B27/C27))/C27+1.96^2/(4*C27^2)))/(1+1.96^2/C27))) -> 0.085069358 | F27: =IF(C27=0,"",MIN(1,((B27/C27)+1.96^2/(2*C27)+1.96*SQRT((B27/C27)*(1-(B27/C27))/C27+1.96^2/(4*C27^2)))/(1+1.96^2/C27))) -> 0.37876636
A29: Site vs city, events with a site point
B30: City corroborated | C30: City not corroborated | D30: Total
A31: Site corroborated | B31: =COUNTIFS(Verdicts!$D$2:$D$101,"<>negative_control",Verdicts!$I$2:$I$101,"<>not_assessable_no_site",Verdicts!$I$2:$I$101,"corroborated",Verdicts!$R$2:$R$101,"corroborated") -> 7 | C31: =COUNTIFS(Verdicts!$D$2:$D$101,"<>negative_control",Verdicts!$I$2:$I$101,"<>not_assessable_no_site",Verdicts!$I$2:$I$101,"corroborated",Verdicts!$R$2:$R$101,"<>corroborated") -> 10 | D31: =B31+C31 -> 17
A32: Site not corroborated (any other verdict) | B32: =COUNTIFS(Verdicts!$D$2:$D$101,"<>negative_control",Verdicts!$I$2:$I$101,"<>not_assessable_no_site",Verdicts!$I$2:$I$101,"<>corroborated",Verdicts!$R$2:$R$101,"corroborated") -> 1 | C32: =COUNTIFS(Verdicts!$D$2:$D$101,"<>negative_control",Verdicts!$I$2:$I$101,"<>not_assessable_no_site",Verdicts!$I$2:$I$101,"<>corroborated",Verdicts!$R$2:$R$101,"<>corroborated") -> 30 | D32: =B32+C32 -> 31
A33: Total | B33: =B31+B32 -> 8 | C33: =C31+C32 -> 40 | D33: =D31+D32 -> 48
A34: On the same events, the site check confirms the D total of the first row; the city check confirms the B column total.

Sheet Weak points
A1: Weak points to defend
A3: # | B3: Issue | C3: Effect on the numbers | D3: What would fix it
A4: 1 | B4: One rule changed after seeing results. Volgograd E002 first came out 'weak': its only FIRMS signal was the separate attack 3 days later, after the timing window. The attribution check now also applies to late signals; E002 is 'not observable'. Recorded in verdict_rules.json. | C4: Rules were written after seeing E002 (test half): call test-half numbers semi-blind. | D4: Fresh events labelled after the rules were fixed.
A5: 2 | B5: Two events confirmed by an image alone: Engels E021 (no clear image before; panel seen before labelling) and Norfolk Southern E038 ('active fire' on an image the cloud mask rates 99.5% cloud, plausibly smoke). | C5: Without them: 15 of 37 instead of 17 of 37 (see Summary). | D5: A second, independent labeller; a clear before image.
A6: 3 | B6: 'Not observable' uses one daytime Sentinel-2 image (around 10:30 local) as a cloud proxy for the whole window; FIRMS also passes at night. | C6: Some 'not observable' could be real misses, or the reverse. | D6: Open-Meteo hourly cloud cover at each overpass time.
A7: 4 | B7: Only 26 controls. | C7: 0 of 26 bounds the false-alarm rate to below about 13% (95%), not to zero. | D7: More controls.

Sheet Corrections
A1: Corrections to earlier statements
A3: Case | B3: Said earlier | C3: Now | D3: Evidence
A4: Proletarsk E019 | B4: City-level background problem (stubble burning, about 10 detections per 5 days) | C4: The city check confirms it | D4: 18 satellite passes with heat within 10 km vs 1.8 expected from the town's own 30-day baseline
A5: Kstovo E016 | B5: (not singled out) | C5: The real city-level false positive | D5: City check says yes from heat 2-4 km from the refinery that was already there the day before; the refinery itself was under cloud

Sheet Rules
A1: Verdict rules (06_VERDICTS/data/verdict_rules.json)
A3: Verdict / rule | B3: Meaning
A4: Timing window | B4: FIRMS signal must start between -3 h and +36 h (hour-precise events), or -12 h and +48 h from 00:00 UTC of the date (day-precise).
A5: corroborated | B5: FIRMS signal (stage 05: new or anomalous, at the site) in the window and not explained by another incident; or a blind image label (fire, smoke, new damage) at a site without flares.
A6: ambiguous_attribution | B6: The signal starts after another known incident at the same site (up to 4 days after the event).
A7: weak | B7: Image 'fire' at a site with flares, or FIRMS signal only after the window (and not explained by another incident).
A8: not_observable | B8: Nothing found, and the site was at least 90% cloud in the first Sentinel-2 image after with no clear image within 5 days; or FIRMS data incomplete.
A9: not_corroborated | B9: Nothing found although the data were there.
A10: not_assessable_no_site | B10: No site point (kept blank on purpose): only the city-level verdict applies.
A11: City level | B11: Distinct satellite passes with a raw FIRMS detection within 10 km of the city point in the window, vs the area's own 30-day baseline; corroborated if Poisson p < 0.01.

Sheet Verdicts
A1: event_id | B1: site_id | C1: split | D1: category | E1: place_name | F1: event_time_utc | G1: time_precision | H1: ground_truth | I1: site_verdict | J1: site_evidence | K1: site_reason | L1: signal_source | M1: flare_site | N1: visual_label | O1: visual_seen_before | P1: s2_status | Q1: firms_complete | R1: city_verdict | S1: city_overpasses_in_window | T1: city_expected_from_baseline | U1: city_p_value
A2: E001 | B2: S01 | C2: test | D2: large_outdoor_fire | E2: Matanzas supertanker base (oil terminal) | F2: 2022-08-05 | G2: day | H2: confirmed | I2: corroborated | J2: FIRMS+image | K2: FIRMS signal from +30.9 h (6 detections in window); image labelled active_fire | L2: 05 filtered | M2: False | N2: active_fire | O2: False | P2: ok | Q2: True | R2: corroborated | S2: 3 | T2: 0 | U2: 0
A3: E002 | B3: S02 | C3: test | D3: large_outdoor_fire | E3: Volgograd refinery (Lukoil) | F3: 2025-01-31 | G3: day | H3: confirmed | I3: not_observable | K3: FIRMS signal only from +71 h, after another incident at the site (incident 2025-02-03); not counted; site 100% cloud in the first Sentinel-2 image after; first clear image +10 d | L3: 05 filtered | M3: True | N3: nothing_visible | O3: False | P3: ok | Q3: True | R3: not_corroborated | S3: 0 | T3: 0.08 | U3: 1
A4: E003 | B4: S02 | C4: test | D4: large_outdoor_fire | E4: Volgograd refinery (Lukoil) | F4: 2025-10-15 | G4: day | H4: confirmed | I4: not_corroborated | K4: no signal although data were available | L4: 05 filtered | M4: True | N4: nothing_visible | O4: False | P4: ok | Q4: True | R4: not_corroborated | S4: 0 | T4: 1.25 | U4: 1
A5: E004 | B5: S03 | C5: calibration | D5: large_outdoor_fire | E5: Moscow refinery (Gazprom Neft, Kapotnya) | F5: 2024-09-01 | G5: day | H5: confirmed | I5: not_corroborated | K5: no signal although data were available | L5: 05 filtered | M5: True | N5: nothing_visible | O5: False | P5: ok | Q5: True | R5: not_corroborated | S5: 0 | T5: 0.17 | U5: 1
A6: E005 | B6: S03 | C6: calibration | D6: large_outdoor_fire | E6: Moscow refinery (Gazprom Neft, Kapotnya) | F6: 2026-06-18 | G6: day | H6: confirmed | I6: not_corroborated | K6: no signal although data were available | L6: 05 filtered | M6: True | N6: nothing_visible | O6: False | P6: no_clear_before | Q6: True | R6: not_corroborated | S6: 0 | T6: 0.25 | U6: 1
A7: E006 | B7: S04 | C7: test | D7: large_outdoor_fire | E7: Yaroslavl refinery (Slavneft-YANOS) | F7: 2026-03-28 | G7: day | H7: confirmed | I7: corroborated | J7: FIRMS | K7: FIRMS signal from +0.0 h (13 detections in window) | L7: 05 filtered | M7: True | N7: nothing_visible | O7: True | P7: ok | Q7: True | R7: corroborated | S7: 4 | T7: 0 | U7: 0
A8: E007 | B8: S05 | C8: calibration | D8: large_outdoor_fire | E8: Kirishi refinery (KINEF) | F8: 2024-03-13 | G8: day | H8: confirmed | I8: not_observable | K8: site 100% cloud in the first Sentinel-2 image after; first clear image never | L8: 05 filtered | M8: True | N8: nothing_visible | O8: False | P8: no_clear_after | Q8: True | R8: not_corroborated | S8: 0 | T8: 0 | U8: 1
A9: E008 | B9: S05 | C9: calibration | D9: large_outdoor_fire | E9: Kirishi refinery (KINEF) | F9: 2025-10-04 | G9: day | H9: confirmed | I9: corroborated | J9: FIRMS | K9: FIRMS signal from +0.1 h (2 detections in window) | L9: 05 filtered | M9: True | N9: not_assessable | O9: False | P9: no_clear_after | Q9: True | R9: not_corroborated | S9: 2 | T9: 2.25 | U9: 0.6575
A10: E009 | B10: S06 | C10: test | D10: large_outdoor_fire | E10: Ryazan refinery (Rosneft) | F10: 2024-05-01 | G10: day | H10: confirmed | I10: not_corroborated | K10: no signal although data were available | L10: 05 filtered | M10: True | N10: nothing_visible | O10: False | P10: ok | Q10: True | R10: not_corroborated | S10: 0 | T10: 0.42 | U10: 1
A11: E010 | B11: S06 | C11: test | D11: large_outdoor_fire | E11: Ryazan refinery (Rosneft) | F11: 2025-09-05 | G11: day | H11: confirmed | I11: corroborated | J11: FIRMS | K11: FIRMS signal from +1.2 h (4 detections in window) | L11: 05 filtered | M11: True | N11: nothing_visible | O11: False | P11: ok | Q11: True | R11: not_corroborated | S11: 1 | T11: 2.08 | U11: 0.8755
A12: E011 | B12: S06 | C12: test | D12: large_outdoor_fire | E12: Ryazan refinery (Rosneft) | F12: 2026-05-15 | G12: day | H12: confirmed | I12: corroborated | J12: FIRMS | K12: FIRMS signal from +9.1 h (4 detections in window); image labelled active_fire at a site with flares (weak) | L12: 05 filtered | M12: True | N12: active_fire | O12: False | P12: ok | Q12: True | R12: corroborated | S12: 9 | T12: 1.08 | U12: 0
A13: E012 | B13: S07 | C13: test | D13: large_outdoor_fire | E13: Tuapse refinery (Rosneft) | F13: 2024-01-25 | G13: day | H13: confirmed | I13: not_corroborated | K13: no signal although data were available | L13: 05 filtered | M13: False | N13: not_assessable | O13: False | P13: no_clear_before | Q13: True | R13: not_corroborated | S13: 0 | T13: 0 | U13: 1
A14: E013 | B14: S07 | C14: test | D14: large_outdoor_fire | E14: Tuapse refinery (Rosneft) | F14: 2024-05-17 | G14: day | H14: confirmed | I14: not_corroborated | K14: no signal although data were available | L14: 05 filtered | M14: False | N14: nothing_visible | O14: False | P14: ok | Q14: True | R14: not_corroborated | S14: 0 | T14: 0.25 | U14: 1
A15: E014 | B15: S08 | C15: calibration | D15: large_outdoor_fire | E15: Perm refinery (Lukoil-Permnefteorgsintez) | F15: 2026-04-29 | G15: day | H15: confirmed | I15: not_corroborated | K15: no signal although data were available | L15: 05 filtered | M15: True | N15: nothing_visible | O15: False | P15: ok | Q15: True | R15: not_corroborated | S15: 0 | T15: 0 | U15: 1
A16: E015 | B16: S09 | C16: calibration | D16: large_outdoor_fire | E16: Kstovo refinery (Lukoil-NORSI) | F16: 2025-01-29 | G16: day | H16: confirmed | I16: not_observable | K16: site 100% cloud in the first Sentinel-2 image after; first clear image +8 d | L16: 05 filtered | M16: True | N16: not_assessable | O16: False | P16: no_clear_before | Q16: True | R16: not_corroborated | S16: 0 | T16: 0 | U16: 1
A17: E016 | B17: S09 | C17: calibration | D17: large_outdoor_fire | E17: Kstovo refinery (Lukoil-NORSI) | F17: 2026-05-20 | G17: day | H17: confirmed | I17: not_observable | K17: site 100% cloud in the first Sentinel-2 image after; first clear image +14 d | L17: 05 filtered | M17: True | N17: nothing_visible | O17: False | P17: ok | Q17: True | R17: corroborated | S17: 10 | T17: 2.67 | U17: 0.0005
A18: E017 | B18: S10 | C18: calibration | D18: large_outdoor_fire | E18: Toropets arsenal (GRAU 107th depot) | F18: 2024-09-18T00:56Z | G18: hour | H18: confirmed | I18: corroborated | J18: FIRMS+image | K18: FIRMS signal from -0.9 h (512 detections in window); image labelled active_fire (image seen before labelling) | L18: 05 filtered | M18: False | N18: active_fire | O18: True | P18: ok | Q18: True | R18: corroborated | S18: 30 | T18: 0 | U18: 0
A19: E018 | B19: S11 | C19: calibration | D19: large_outdoor_fire | E19: Feodosia marine oil terminal | F19: 2024-10-07 | G19: day | H19: confirmed | I19: not_assessable_no_site | K19: no site point (kept blank on purpose) | M19: False | P19: skipped_no_site_point | Q19: True | R19: corroborated | S19: 10 | T19: 0 | U19: 0
A20: E019 | B20: S12 | C20: test | D20: large_outdoor_fire | E20: Kavkaz oil depot, Proletarsk | F20: 2024-08-18 | G20: day | H20: confirmed | I20: not_assessable_no_site | K20: no site point (kept blank on purpose) | M20: False | P20: skipped_no_site_point | Q20: True | R20: corroborated | S20: 18 | T20: 1.83 | U20: 0
A21: E020 | B21: S13 | C21: calibration | D21: large_outdoor_fire | E21: Garyville refinery (Marathon) | F21: 2023-08-25 | G21: day | H21: confirmed | I21: weak | J21: image | K21: image labelled active_fire at a site with flares (weak) | L21: 05 filtered | M21: True | N21: active_fire | O21: False | P21: ok | Q21: True | R21: not_corroborated | S21: 12 | T21: 8.83 | U21: 0.1811
A22: E021 | B22: S14 | C22: calibration | D22: large_outdoor_fire | E22: Kombinat Kristall oil depot (Rosrezerv), Engels | F22: 2025-01-07T23:00Z | G22: hour | H22: confirmed | I22: corroborated | J22: image | K22: image labelled new_damage_or_scar (image seen before labelling) | L22: 05 filtered | M22: False | N22: new_damage_or_scar | O22: True | P22: no_clear_before | Q22: True | R22: not_corroborated | S22: 0 | T22: 0 | U22: 1
A23: E022 | B23: S15 | C23: calibration | D23: large_outdoor_fire | E23: Rosneft fuel depot, Belgorod | F23: 2022-04-01 | G23: day | H23: confirmed | I23: not_assessable_no_site | K23: no site point (kept blank on purpose) | M23: False | P23: skipped_no_site_point | Q23: True | R23: not_corroborated | S23: 3 | T23: 1 | U23: 0.0803
A24: E023 | B24: S16 | C24: calibration | D24: large_outdoor_fire | E24: Saky air base, Novofedorivka (Crimea) | F24: 2022-08-09 | G24: day | H24: confirmed | I24: not_corroborated | K24: no signal although data were available | L24: 05 filtered | M24: False | N24: nothing_visible | O24: False | P24: ok | Q24: True | R24: not_corroborated | S24: 0 | T24: 0 | U24: 1
A25: E024 | B25: S20 | C25: calibration | D25: industrial_fire | E25: Marywilska 44 shopping centre, Warsaw | F25: 2024-05-12T01:30Z | G25: hour | H25: confirmed | I25: corroborated | J25: FIRMS | K25: FIRMS signal from +0.1 h (2 detections in window) | L25: 05 filtered | M25: False | N25: nothing_visible | O25: False | P25: ok | Q25: True | R25: not_corroborated | S25: 1 | T25: 0.6 | U25: 0.4489
A26: E025 | B26: S21 | C26: test | D26: industrial_fire | E26: BioLab plant, Conyers GA | F26: 2024-09-29T09:00Z | G26: hour | H26: confirmed | I26: not_assessable_no_site | K26: no site point (kept blank on purpose) | M26: False | P26: skipped_no_site_point | Q26: True | R26: corroborated | S26: 3 | T26: 0 | U26: 0
A27: E026 | B27: S22 | C27: test | D27: industrial_fire | E27: Moss Landing battery storage facility (Vistra) | F27: 2025-01-16 | G27: day | H27: confirmed | I27: corroborated | J27: FIRMS+image | K27: FIRMS signal from +33.5 h (8 detections in window); image labelled active_fire | L27: 05 filtered | M27: False | N27: active_fire | O27: False | P27: ok | Q27: True | R27: corroborated | S27: 6 | T27: 0.25 | U27: 0
A28: E027 | B28: S23 | C28: calibration | D28: industrial_fire | E28: BM Container Depot, Sitakunda | F28: 2022-06-04T15:00Z | G28: hour | H28: confirmed | I28: corroborated | J28: FIRMS+image | K28: FIRMS signal from +3.7 h (19 detections in window); image labelled active_fire | L28: 05 filtered | M28: False | N28: active_fire | O28: False | P28: no_clear_before | Q28: True | R28: not_corroborated | S28: 0 | T28: 0.05 | U28: 1
A29: E028 | B29: S24 | C29: calibration | D29: industrial_fire | E29: Zagorsk Optical-Mechanical Plant (ZOMZ), Sergiyev Posad | F29: 2023-08-09 | G29: day | H29: confirmed | I29: not_observable | K29: site 100% cloud in the first Sentinel-2 image after; first clear image +8 d | L29: 05 filtered | M29: False | N29: nothing_visible | O29: False | P29: ok | Q29: True | R29: not_corroborated | S29: 0 | T29: 0 | U29: 1
A30: E029 | B30: S25 | C30: test | D30: industrial_fire | E30: My Way Trading plastics storage site, Richmond IN | F30: 2023-04-11T19:00Z | G30: hour | H30: confirmed | I30: corroborated | J30: FIRMS+image | K30: FIRMS signal from +0.3 h (21 detections in window); image labelled active_fire | L30: 05 filtered | M30: False | N30: active_fire | O30: False | P30: ok | Q30: True | R30: corroborated | S30: 12 | T30: 0.43 | U30: 0
A31: E030 | B31: S26 | C31: calibration | D31: industrial_fire | E31: Elastik plant, Lesnoy (Shilovsky district, Ryazan oblast) | F31: 2025-08-15T07:41Z | G31: hour | H31: confirmed | I31: not_assessable_no_site | K31: no site point (kept blank on purpose) | M31: False | P31: skipped_no_site_point | Q31: True | R31: not_corroborated | S31: 0 | T31: 0 | U31: 1
A32: E031 | B32: S27 | C32: calibration | D32: industrial_fire | E32: Mega Khimki shopping centre (OBI) | F32: 2022-12-09 | G32: day | H32: confirmed | I32: not_assessable_no_site | K32: no site point (kept blank on purpose) | M32: False | P32: skipped_no_site_point | Q32: True | R32: not_corroborated | S32: 0 | T32: 0 | U32: 1
A33: E032 | B33: S28 | C33: calibration | D33: industrial_fire | E33: Amstor shopping mall, Kremenchuk | F33: 2022-06-27 | G33: day | H33: confirmed | I33: not_corroborated | K33: no signal although data were available | L33: 05 filtered | M33: False | N33: nothing_visible | O33: False | P33: no_clear_before | Q33: True | R33: not_corroborated | S33: 0 | T33: 0 | U33: 1
A34: E033 | B34: S29 | C34: calibration | D34: industrial_fire | E34: Mradi area gas depot, Embakasi, Nairobi | F34: 2024-02-01T20:30Z | G34: hour | H34: confirmed | I34: not_assessable_no_site | K34: no site point (kept blank on purpose) | M34: False | P34: skipped_no_site_point | Q34: True | R34: not_corroborated | S34: 0 | T34: 0.16 | U34: 1
A35: E034 | B35: S30 | C35: calibration | D35: industrial_fire | E35: Energy Transfer pipeline valve station, Deer Park / La Porte TX | F35: 2024-09-16T14:55Z | G35: hour | H35: confirmed | I35: not_assessable_no_site | K35: no site point (kept blank on purpose) | M35: False | P35: skipped_no_site_point | Q35: True | R35: not_corroborated | S35: 6 | T35: 4.6 | U35: 0.315
A36: E035 | B36: S31 | C36: calibration | D36: industrial_fire | E36: Shell Deer Park Chemicals (olefins unit) | F36: 2023-05-05T19:56Z | G36: hour | H36: confirmed | I36: not_assessable_no_site | K36: no site point (kept blank on purpose) | M36: False | P36: skipped_no_site_point | Q36: True | R36: not_corroborated | S36: 2 | T36: 2.33 | U36: 0.6758
A37: E036 | B37: S32 | C37: calibration | D37: industrial_fire | E37: Diehl Metal Applications plant, Berlin-Lichterfelde | F37: 2024-05-03 | G37: day | H37: confirmed | I37: not_assessable_no_site | K37: no site point (kept blank on purpose) | M37: False | P37: skipped_no_site_point | Q37: True | R37: not_corroborated | S37: 0 | T37: 0 | U37: 1
A38: E037 | B38: S33 | C38: calibration | D38: industrial_fire | E38: Crocus City Hall, Krasnogorsk | F38: 2024-03-22T16:58Z | G38: hour | H38: confirmed | I38: not_observable | K38: site 100% cloud in the first Sentinel-2 image after; first clear image +9 d | L38: 05 filtered | M38: False | N38: nothing_visible | O38: False | P38: ok | Q38: True | R38: not_corroborated | S38: 0 | T38: 0 | U38: 1
A39: E038 | B39: S34 | C39: calibration | D39: industrial_fire | E39: Norfolk Southern derailment site, East Palestine OH | F39: 2023-02-04T01:55Z | G39: hour | H39: confirmed | I39: corroborated | J39: image | K39: image labelled active_fire | L39: 05 filtered | M39: False | N39: active_fire | O39: False | P39: no_clear_after | Q39: True | R39: not_corroborated | S39: 0 | T39: 0 | U39: 1
A40: E039 | B40: S35 | C40: calibration | D40: industrial_fire | E40: Wildberries warehouse, Shushary (St Petersburg) | F40: 2024-01-13 | G40: day | H40: confirmed | I40: not_assessable_no_site | K40: no site point (kept blank on purpose) | M40: False | P40: skipped_no_site_point | Q40: True | R40: not_corroborated | S40: 0 | T40: 0 | U40: 1
...
